<robot name = "robot">
    <link name="Body">
        <inertial>
            <origin xyz="0 0 0.5" rpy="0 0 0"/>
            <mass value="1" />
            <inertia ixx="10000" ixy="0" ixz="0" iyy="10000" iyz="0" izz="10000" />
        </inertial>
        <visual>
            <origin xyz="0 0 0.5" rpy="0 0 0"/>
            <geometry>
                <box size="4 2 1" />
            </geometry>
            <material name="Cyan">
                <color rgba="0 1.0 1.0 1.0"/>
            </material>
        </visual>
        <collision>
            <origin xyz="0 0 0.5" rpy="0 0 0"/>
            <geometry>
                <box size="4 2 1" />
            </geometry>
        </collision>
    </link>
    <joint name="Body_Lwheel" type="revolute">
       <parent link="Body"/>
       <child  link="Lwheel"/>
       <origin rpy="0 0 0" xyz="0 1.0 0.5" />
       <axis xyz="0 1 0"/>
       <limit effort="0.0" velocity="0.0"/>
    </joint>
    <link name="Lwheel">
        <inertial>
            <origin xyz="0 0.5 0" rpy="0 0 0"/>
            <mass value="1" />
            <inertia ixx="100" ixy="0" ixz="0" iyy="100" iyz="0" izz="100" />
        </inertial>
        <visual>
            <origin xyz="0 0.5 0" rpy="0 0 0"/>
            <geometry>
                <box size="2 1 2" />
            </geometry>
            <material name="Cyan">
                <color rgba="0 1.0 1.0 1.0"/>
            </material>
        </visual>
        <collision>
            <origin xyz="0 0.5 0" rpy="0 0 0"/>
            <geometry>
                <box size="2 1 2" />
            </geometry>
        </collision>
    </link>
    <joint name="Body_Rwheel" type="revolute">
       <parent link="Body"/>
       <child  link="Rwheel"/>
       <origin rpy="0 0 0" xyz="0 -1.0 0.5" />
       <axis xyz="0 1 0"/>
       <limit effort="0.0"  velocity="0.0"/>
    </joint>
    <link name="Rwheel">
        <inertial>
            <origin xyz="0 -0.5 0" rpy="0 0 0"/>
            <mass value="1" />
            <inertia ixx="100" ixy="0" ixz="0" iyy="100" iyz="0" izz="100" />
        </inertial>
        <visual>
            <origin xyz="0 -0.5 0" rpy="0 0 0"/>
            <geometry>
                <box size="2 1 2" />
            </geometry>
            <material name="Cyan">
                <color rgba="0 1.0 1.0 1.0"/>
            </material>
        </visual>
        <collision>
            <origin xyz="0 -0.5 0" rpy="0 0 0"/>
            <geometry>
                <box size="2 1 2" />
            </geometry>
        </collision>
    </link>
</robot>
